Workbook
Name Company_Name: Control!$B$3
Name Date: Control!$B$2
Name Days_In_Year: #REF!
Name Debt_Amount: 'Merger-Model'!$L$9
Name Debt_Date: Control!$B$2
Name Diluted_Shares: Control!$B$5
Name Enterprise_Value: Control!$B$7
Name Equity_Value: Control!$B$6
Name Hist_Year: Control!$B$8
Name Purchase_Price: 'Merger-Model'!$F$7
Name Seller_Name: Control!$B$15
Name Seller_Share_Price: Control!$B$16
Name Share_Price: Control!$B$4
Name Tax_Rate: Control!$B$11
Name Units: Control!$B$9
Name Company_Name: #REF!
Name Date: #REF!
Name Debt_Amount: #REF!
Name Debt_Date: #REF!
Name Diluted_Shares: #REF!
Name Enterprise_Value: #REF!
Name Equity_Value: #REF!
Name Hist_Year: #REF!
Name Purchase_Price: #REF!
Name Seller_Name: #REF!
Name Seller_Share_Price: #REF!
Name Share_Price: #REF!
Name Tax_Rate: #REF!
Name Units: #REF!
Name Company_Name: #REF!
Name Date: #REF!
Name Debt_Amount: #REF!
Name Debt_Date: #REF!
Name Diluted_Shares: #REF!
Name Enterprise_Value: #REF!
Name Equity_Value: #REF!
Name Hist_Year: #REF!
Name Purchase_Price: #REF!
Name Seller_Name: #REF!
Name Seller_Share_Price: #REF!
Name Share_Price: #REF!
Name Tax_Rate: #REF!
Name Units: #REF!
Name Company_Name: #REF!
Name Date: #REF!
Name Debt_Amount: #REF!
Name Debt_Date: #REF!
Name Diluted_Shares: #REF!
Name Enterprise_Value: #REF!
Name Equity_Value: #REF!
Name Hist_Year: #REF!
Name Purchase_Price: #REF!
Name Seller_Name: #REF!
Name Seller_Share_Price: #REF!
Name Share_Price: #REF!
Name Tax_Rate: #REF!
Name Units: #REF!
Name Company_Name: #REF!
Name Date: #REF!
Name Debt_Amount: #REF!

Sheet Cover Page
B2: M&A MERGER MODEL
B3: Acquisition of PT Solusi Sinergi Digital Tbk. (WIFI) by PT Sarana Menara Nusantara Tbk. (TOWR)
B5: Deal Summary
B7: Acquirer | E7: ='Merger-Model'!F33
B8: Target | E8: ='Merger-Model'!L33
B9: Offer Price / Share (IDR) | E9: ='Merger-Model'!F7
B10: Takeover Premium | E10: ='Financing_Mix'!B4
B11: Equity Purchase Price (IDR mm) | E11: ='Merger-Model'!L7
B12: Offer Enterprise Value (IDR mm) | E12: ='M&A_Valuation'!C33
B13: Consideration (Cash / Debt / Stock) | E13: =TEXT('Merger-Model'!F8,"0%")&" / "&TEXT('Merger-Model'!F9,"0%")&" / "&TEXT('Merger-Model'!F10,"0%")
B14: Total Goodwill Created (IDR mm) | E14: ='Merger-Model'!F28
B15: Synergy NPV — perpetuity (IDR mm) | E15: ='M&A_Valuation'!C35
B16: Pro Forma Net Debt / EBITDA | E16: ='Financing_Mix'!B41
B17: EPS Accretion / (Dilution) | E17: ='M&A_Valuation'!J9
B19: Contents
B20: • Deal Assumptions & Analysis
B21: • TOWR VALUATION · WIFI VALUATION (standalone DCF)
B22: • WIFI BLENDED · Football Field
B23: • Merger-Model · Synergy_Schedule · Returns Analysis
B25: Figures in IDR millions unless stated · Green = live link to model · Prepared for FFI Finals

Sheet Deal Assumptions & Analysis
A1: Merger Assumptions — TOWR (Acquirer) & WIFI (Target)
A2: PT Sarana Menara Nusantara Tbk. acquires PT Solusi Sinergi Digital Tbk. · Figures in IDR millions, shares in ’000, prices in IDR/share
A4: Transaction Inputs | F4: Financing & Synergies
A5: Acquirer Name | D5: ='Merger-Model'!F33 | F5: % Cash | H5: ='Merger-Model'!F8
A6: Target Name | D6: ='Merger-Model'!L33 | F6: % Debt | H6: ='Merger-Model'!F9
A7: Acquirer Share Price | D7: ='Merger-Model'!F34 | F7: % Stock | H7: ='Merger-Model'!F10
A8: Target Share Price | D8: ='Merger-Model'!L34 | F8: Debt Interest Rate | H8: ='Merger-Model'!L11
A9: Transaction Close Date | D9: 46387 | F9: Foregone Cash Rate | H9: ='Merger-Model'!F11
A10: Financial Reporting Units | D10: IDR mm | F10: Purchase Premium | H10: ='Financing_Mix'!B4
A11: Currency | D11: IDR
A12: Acquirer FD Shares (’000) | D12: ='Merger-Model'!F35 | F12: Synergy NPV — perpetuity | H12: ='M&A_Valuation'!C35
A13: Target FD Shares (’000) | D13: ='Merger-Model'!L35 | F13: Synergy NPV — exit multiple | H13: ='M&A_Valuation'!C36
A14: Acquirer Tax Rate | D14: ='Merger-Model'!F38 | F14: Buyer standalone EPS (IDR) | H14: ='M&A_Valuation'!J7
A15: Target Tax Rate | D15: ='Merger-Model'!L38 | F15: Pro forma combined EPS (IDR) | H15: ='M&A_Valuation'!J8
A18: Purchase Price | F18: Sources & Uses of Cash
A19: Target Share Price | D19: ='Merger-Model'!L34 | F19: Sources of Cash | K19: Uses of Cash
A20: Takeover Premium | D20: ='Financing_Mix'!B4 | F20: Cash on Hand | H20: ='Merger-Model'!L8 | K20: Cash Consideration | M20: ='Merger-Model'!L8
A21: Offer Price / Share | D21: ='Merger-Model'!F7 | F21: New Debt Issued | H21: ='Merger-Model'!L9 | K21: Debt Consideration | M21: ='Merger-Model'!L9
A22: Target FD Shares (’000) | D22: ='Merger-Model'!L35 | F22: Stock Issued | H22: ='Financing_Mix'!B28 | K22: Stock Consideration | M22: ='Financing_Mix'!B28
A23: Equity Purchase Price | D23: ='Merger-Model'!L7 | F23: Total Sources | H23: =SUM(H20:H22) | K23: Total Uses | M23: =SUM(M20:M22)
A24: Less: Target Cash | D24: =-'Merger-Shares-BS'!E16
A25: Plus: Target Debt | D25: ='Merger-Shares-BS'!E17
A26: Plus: Minority Interest | D26: ='Merger-Shares-BS'!E18
A27: Offer Enterprise Value | D27: ='M&A_Valuation'!C33
A30: Goodwill & Purchase Price Allocation | F30: Accretion / (Dilution) & Leverage
A31: Equity Purchase Price | D31: ='Merger-Model'!F19 | F31: Acquirer Standalone EPS (IDR) | H31: ='M&A_Valuation'!J7
A32: Less: Target Book Value | D32: ='Merger-Model'!F20 | F32: Pro Forma Combined EPS (IDR) | H32: ='M&A_Valuation'!J8
A33: Plus: Write-off Existing Goodwill | D33: ='Merger-Model'!F21 | F33: EPS Accretion / (Dilution) % | H33: ='M&A_Valuation'!J9
A34: Total Allocable Premium | D34: ='Merger-Model'!F22
A35: Less: Write-up of Intangibles | D35: ='Merger-Model'!F25 | F35: Pro Forma Gross Debt (IDR mm) | H35: ='Financing_Mix'!B39
A36: Less: Write-down of DTL | D36: ='Merger-Model'!F26 | F36: Pro Forma Net Debt / EBITDA | H36: ='Financing_Mix'!B41
A37: Plus: New Deferred Tax Liability | D37: ='Merger-Model'!F27 | F37: Pro Forma Share Count (’000) | H37: ='Financing_Mix'!B42
A38: Total Goodwill Created | D38: ='Merger-Model'!F28
A40: Legend: | B40: Blue = input | D40: Green = link to another sheet | H40: Black = formula

Sheet Control
A1: TOWR + WIFI merger controls
A2: Model date | B2: 2026-04-02
A3: Buyer name | B3: PT Sarana Menara Nusantara Tbk.
A4: Buyer share price (IDR) | B4: 434
A5: Buyer diluted shares (000) | B5: 58202694
A6: Buyer equity value (IDR mm) | B6: =B4*B5/1000
A7: Buyer enterprise value (IDR mm) | B7: =B6+('TOWR-3-Statements'!G80+'TOWR-3-Statements'!G87-'TOWR-3-Statements'!G59+'TOWR-3-Statements'!G98)/1000
A8: Last historical year | B8: 2025
A9: Units (share count basis) | B9: 1000
A10: Premium to seller price | B10: ='Merger-Shares-BS'!E9/'Merger-Shares-BS'!E8-1
A11: Buyer tax rate | B11: =-'TOWR-3-Statements'!G50/'TOWR-3-Statements'!G48
A12: Foregone cash interest rate | B12: 0.02
A13: Debt interest rate | B13: 0.07
A14: % of seller acquired | B14: 0.51
A15: Seller name | B15: PT Solusi Sinergi Digital Tbk.
A16: Seller share price (IDR) | B16: 2090
A17: Seller diluted shares (000) | B17: 5308549
A18: Seller equity value (IDR mm) | B18: =B16*B17/1000
A19: Seller enterprise value (IDR mm) | B19: =B18+('WIFI 3-Statement Model'!H66+'WIFI 3-Statement Model'!H71-'WIFI 3-Statement Model'!H51+'WIFI 3-Statement Model'!H78)/1000

Sheet Merger-Model
B2: ="Merger Model - "&TEXT(Company_Name,"")&" and "&Seller_Name
B3: ($ in IDR mm, except per share amounts in IDR and share counts in thousands)
B5: Transaction Assumptions
B7: Per Share Purchase Price: | F7: ='WIFI BLENDED'!D9 | H7: Equity Purchase Price: | L7: ='Merger-Shares-BS'!J15*Control!$B$14
B8: % Cash: | F8: 0 | H8: Cash Used: | L8: =F8*L7
B9: % Debt: | F9: 0.6 | H9: Debt Issued: | L9: =F9*L7
B10: % Stock: | F10: =1-F8-F9 | H10: New Shares Issued: | L10: =F10*L7/F34*Units
B11: Foregone Cash Interest Rate: | F11: =Control!$B$12 | H11: Debt Interest Rate: | L11: =Control!$B$13
H13: Revenue Synergy COGS %: | L13: 0.6
B16: Goodwill Creation & Balance Sheet Adjustments
B18: Goodwill Calculation: | H18: Fixed Asset Write-Up:
B19: Equity Purchase Price: | F19: =L7 | H19: PP&E Write-Up %: | L19: 0
B20: Less: Seller Book Value: | F20: =-'Merger-Shares-BS'!J62 | H20: PP&E Write-Up Amount: | L20: =L19*'Merger-Shares-BS'!J36
B21: Plus: Write-Off of Existing Goodwill: | F21: ='Merger-Shares-BS'!J37 | H21: Depreciation Period (Years): | L21: 8
B22: Total Allocable Purchase Premium: | F22: =F19+F20+F21
H23: Intangible Asset Write-Up:
B24: Less: Write-Up of PP&E: | F24: =-L20 | H24: Purchase Price to Allocate: | L24: =F22
B25: Less: Write-Up of Intangibles: | F25: =-L26 | H25: % Allocated to Intangibles: | L25: 0.2
B26: Less: Write-Down of DTL: | F26: =-'Merger-Shares-BS'!J52 | H26: Intangibles Write-Up Amount: | L26: =0.3*(L7-Control!$B$14*'Merger-Shares-BS'!J62)
B27: Plus: New Deferred Tax Liability: | F27: =L29 | H27: Amortization Period (Years): | L27: 15
B28: Total Goodwill Created: | F28: =0.7*(L7-Control!$B$14*'Merger-Shares-BS'!J62)
H29: New Deferred Tax Liability: | L29: 0
H30: Non-Controlling Interest (new): | L30: =(1-Control!$B$14)*'Merger-Shares-BS'!J62
B31: Buyer - Financial Profile | H31: Seller - Financial Profile
B33: Buyer Name: | F33: =Company_Name | H33: Seller Name: | L33: =Seller_Name
B34: Share Price: | F34: =Share_Price | H34: Share Price: | L34: =Seller_Share_Price
B35: Diluted Shares Outstanding: | F35: =Diluted_Shares | H35: Diluted Shares Outstanding: | L35: =Control!$B$17
B36: Diluted Equity Value: | F36: =Equity_Value | H36: Diluted Equity Value: | L36: =Control!$B$18
B37: Enterprise Value: | F37: =Enterprise_Value | H37: Enterprise Value: | L37: =Control!$B$19
B38: Tax Rate: | F38: =Control!$B$11 | H38: Tax Rate: | L38: =-'WIFI 3-Statement Model'!H43/'WIFI 3-Statement Model'!H42
B40: Buyer - Income Statement | H40: Seller - Income Statement
E42: 2025 | F42: 2026 | K42: 2025 | L42: 2026
B43: Revenue: | E43: ='TOWR-3-Statements'!G30/1000 | F43: ='TOWR-3-Statements'!H30/1000 | H43: Revenue: | K43: ='WIFI 3-Statement Model'!H28/1000 | L43: ='WIFI 3-Statement Model'!I28/1000
B44: Cost of Goods Sold: | E44: =-('TOWR-3-Statements'!G31+'TOWR-3-Statements'!G32)/1000 | F44: =-('TOWR-3-Statements'!H31+'TOWR-3-Statements'!H32)/1000 | H44: Cost of Goods Sold: | K44: =-'WIFI 3-Statement Model'!H29/1000 | L44: =-'WIFI 3-Statement Model'!I29/1000
B45: Gross Profit: | E45: =E43-E44 | F45: =F43-F44 | H45: Gross Profit: | K45: =K43-K44 | L45: =L43-L44
B47: Operating Expenses: | E47: =E45-E53-E49-E50-E51 | F47: =F45-F53-F49-F50-F51 | H47: Operating Expenses: | K47: =K45-K53-K49-K50-K51 | L47: =L45-L53-L49-L50-L51
B49: Depreciation of PP&E: | E49: =-'TOWR-3-Statements'!G31/1000 | F49: =-'TOWR-3-Statements'!H31/1000 | H49: Depreciation of PP&E: | K49: ='WIFI 3-Statement Model'!H36/1000 | L49: ='WIFI 3-Statement Model'!I36/1000
B50: Amortization of Intangibles: | E50: 0 | F50: 0 | H50: Amortization of Intangibles: | K50: 0 | L50: 0
B51: Stock-Based Compensation: | E51: 0 | F51: 0 | H51: Stock-Based Compensation: | K51: 0 | L51: 0
B53: Operating Income: | E53: ='TOWR-3-Statements'!G38/1000 | F53: ='TOWR-3-Statements'!H38/1000 | H53: Operating Income: | K53: ='WIFI 3-Statement Model'!H34/1000 | L53: ='WIFI 3-Statement Model'!I34/1000
...

Sheet Merger-Shares-BS
B2: ="Merger Model - Seller Diluted Share Count & Combined Balance Sheets"
B3: ($ in IDR millions, except per share amounts in IDR and share counts in thousands)
B5: Diluted Share & Enterprise Value Calculations - Seller
B7: Company Name: | E7: =Seller_Name | L7: Options Calculations - Current Price:
B8: Share Price: | E8: =Seller_Share_Price
B9: Offer Price Per Share: | E9: =Purchase_Price | G9: Effective Tax Rate: | J9: ='TOWR-3-Statements'!H176*-1 | N9: Exercise
L10: Name | M10: Number | N10: Price | O10: Dilution
B11: Current Share Price: | G11: Purchase Price: | L11: Tranche A | M11: 0 | N11: 0 | O11: =IF(N11>Seller_Share_Price,0,M11-M11*N11/Seller_Share_Price)
B12: Basic Shares Outstanding: | E12: =Control!$B$17 | G12: Basic Shares Outstanding: | J12: =E12 | L12: Tranche B
B13: Basic Equity Value: | E13: =E12/Units*Seller_Share_Price | G13: Basic Equity Value: | J13: =J12/Units*E9 | L13: Total | O13: 0
B14: Diluted Shares Outstanding: | E14: =E12+O13 | G14: Diluted Shares Outstanding: | J14: =J12+O21
B15: Diluted Equity Value: | E15: =E14/Units*Seller_Share_Price | G15: Diluted Equity Value: | J15: =J14/Units*E9 | L15: Options Calculations - Purchase Price:
B16: Less: Cash & Investments | E16: ='WIFI 3-Statement Model'!H51/1000 | G16: Less: Cash & Investments | J16: =E16
B17: Plus: Debt | E17: =('WIFI 3-Statement Model'!H66+'WIFI 3-Statement Model'!H71)/1000 | G17: Plus: Debt | J17: =E17 | N17: Exercise
B18: Plus: Minority Interest | E18: ='WIFI 3-Statement Model'!H78/1000 | G18: Plus: Minority Interest | J18: =E18 | L18: Name | M18: Number | N18: Price | O18: Dilution
B19: Plus: Preferred Stock | E19: 0 | G19: Plus: Preferred Stock | J19: =E19 | L19: Tranche A | M19: 10470 | N19: 38.57 | O19: =IF(N19>E9,0,M19-M19*N19/E9)
B20: Plus: Other Liabilities | E20: 0 | G20: Plus: Other Liabilities | J20: =E20 | L20: Tranche B
B21: Enterprise Value: | E21: =E15-E16+E17+E18+E19+E20 | G21: Enterprise Value: | J21: =J15-J16+J17+J18+J19+J20 | L21: Total | O21: 0
B23: Balance Sheets - Buyer, Seller & Combined
B25: Assets: | H25: Buyer | J25: Seller | L25: Adjustments | N25: Combined
B26: Current Assets:
B27: Cash & Short-Term Securities: | H27: ='TOWR-3-Statements'!G59/1000 | J27: ='WIFI 3-Statement Model'!H51/1000 | L27: =-'Merger-Model'!L8 | N27: =H27+J27+L27
B28: Accounts Receivable: | H28: ='TOWR-3-Statements'!G60/1000 | J28: ='WIFI 3-Statement Model'!H52/1000 | L28: 0 | N28: =H28+J28+L28
B29: Inventory: | H29: ='TOWR-3-Statements'!G61/1000 | J29: ='WIFI 3-Statement Model'!H53/1000 | L29: 0 | N29: =H29+J29+L29
B30: Deferred Tax Assets: | H30: 0 | J30: 0 | L30: 0 | N30: =H30+J30+L30
B31: Other Current Assets: | H31: =('TOWR-3-Statements'!G62+'TOWR-3-Statements'!G63)/1000 | J31: =('WIFI 3-Statement Model'!H54+'WIFI 3-Statement Model'!H55)/1000 | L31: 0 | N31: =H31+J31+L31
B32: Total Current Assets: | H32: =SUM(H27:H31) | J32: =SUM(J27:J31) | L32: =SUM(L27:L31) | N32: =SUM(N27:N31)
B34: Long-Term Assets:
B35: Long-Term Securities: | H35: =('TOWR-3-Statements'!G67+'TOWR-3-Statements'!G68+'TOWR-3-Statements'!G69+'TOWR-3-Statements'!G70)/1000 | J35: =0 | L35: 0 | N35: =H35+J35+L35
B36: Plants, Property & Equipment: | H36: ='TOWR-3-Statements'!G71/1000 | J36: ='WIFI 3-Statement Model'!H58/1000 | L36: ='Merger-Model'!L20 | N36: =H36+J36+L36
B37: Goodwill: | H37: 0 | J37: 0 | L37: ='Merger-Model'!F28 | N37: =H37+J37+L37
B38: Other Intangible Assets: | H38: =('TOWR-3-Statements'!G72+'TOWR-3-Statements'!G73)/1000 | J38: =('WIFI 3-Statement Model'!H59+'WIFI 3-Statement Model'!H60)/1000 | L38: ='Merger-Model'!L26 | N38: =H38+J38+L38
B39: Other Assets: | H39: 0 | J39: 0 | L39: 0 | N39: =H39+J39+L39
B40: Total Assets: | H40: =SUM(H35:H39)+H32 | J40: =SUM(J35:J39)+J32 | L40: =SUM(L35:L39)+L32 | N40: =SUM(N35:N39)+N32
B42: Liabilities & Shareholders' Equity:
B43: Current Liabilities:
B44: Accounts Payable: | H44: ='TOWR-3-Statements'!G79/1000 | J44: ='WIFI 3-Statement Model'!H65/1000 | L44: 0 | N44: =H44+J44+L44
B45: Accrued Expenses: | H45: =('TOWR-3-Statements'!G81+'TOWR-3-Statements'!G82+'TOWR-3-Statements'!G83)/1000 | J45: =('WIFI 3-Statement Model'!H67+'WIFI 3-Statement Model'!H68)/1000 | L45: 0 | N45: =H45+J45+L45
B46: Deferred Revenue: | H46: 0 | J46: 0 | L46: 0 | N46: =H46+J46+L46
B47: Total Current Liabilities: | H47: =SUM(H44:H46) | J47: =SUM(J44:J46) | L47: =SUM(L44:L46) | N47: =SUM(N44:N46)
...

Sheet Synergy_Schedule
B2: TOWR + WIFI synergy schedule
B3: IDR mm unless stated otherwise
B5: Assumptions / drivers
B6: Tax rate | C6: =Control!$B$11
B7: Discount rate / WACC | C7: 0.09
B8: Terminal growth rate | C8: 0.03
B9: Exit EBITDA multiple | C9: 8.5
B10: Revenue synergy % (LEGACY — superseded by bottom-up) | C10: ='Merger-Model'!F13
B11: Revenue synergy COGS % | C11: ='Merger-Model'!$L$13
B12: Cost synergy % (LEGACY — superseded by bottom-up) | C12: ='Merger-Model'!$F$14
B13: Integration cost as % of annual cost synergies | C13: 0.5
B15: Recurring synergy schedule
B16: Fiscal year | C16: ='WIFI 3-Statement Model'!I2 | D16: ='WIFI 3-Statement Model'!J2 | E16: ='WIFI 3-Statement Model'!K2 | F16: ='WIFI 3-Statement Model'!L2 | G16: ='WIFI 3-Statement Model'!M2
B17: Synergy ramp | C17: 0.5 | D17: 0.75 | E17: 1 | F17: 1 | G17: 1
B19: Seller revenue | C19: =IFERROR('WIFI 3-Statement Model'!I28/1000,0) | D19: =IFERROR('WIFI 3-Statement Model'!J28/1000,0) | E19: =IFERROR('WIFI 3-Statement Model'!K28/1000,0) | F19: =IFERROR('WIFI 3-Statement Model'!L28/1000,0) | G19: =IFERROR('WIFI 3-Statement Model'!M28/1000,0)
B20: Seller gross profit | C20: =IFERROR('WIFI 3-Statement Model'!I30/1000,0) | D20: =IFERROR('WIFI 3-Statement Model'!J30/1000,0) | E20: =IFERROR('WIFI 3-Statement Model'!K30/1000,0) | F20: =IFERROR('WIFI 3-Statement Model'!L30/1000,0) | G20: =IFERROR('WIFI 3-Statement Model'!M30/1000,0)
B21: Seller operating income | C21: =IFERROR('WIFI 3-Statement Model'!I34/1000,0) | D21: =IFERROR('WIFI 3-Statement Model'!J34/1000,0) | E21: =IFERROR('WIFI 3-Statement Model'!K34/1000,0) | F21: =IFERROR('WIFI 3-Statement Model'!L34/1000,0) | G21: =IFERROR('WIFI 3-Statement Model'!M34/1000,0)
B22: Seller depreciation | C22: =IFERROR('WIFI 3-Statement Model'!I36/1000,0) | D22: =IFERROR('WIFI 3-Statement Model'!J36/1000,0) | E22: =IFERROR('WIFI 3-Statement Model'!K36/1000,0) | F22: =IFERROR('WIFI 3-Statement Model'!L36/1000,0) | G22: =IFERROR('WIFI 3-Statement Model'!M36/1000,0)
B23: Seller OpEx excl. D&A | C23: =IFERROR(-('WIFI 3-Statement Model'!I32+'WIFI 3-Statement Model'!I33)/1000,0) | D23: =IFERROR(-('WIFI 3-Statement Model'!J32+'WIFI 3-Statement Model'!J33)/1000,0) | E23: =IFERROR(-('WIFI 3-Statement Model'!K32+'WIFI 3-Statement Model'!K33)/1000,0) | F23: =IFERROR(-('WIFI 3-Statement Model'!L32+'WIFI 3-Statement Model'!L33)/1000,0) | G23: =IFERROR(-('WIFI 3-Statement Model'!M32+'WIFI 3-Statement Model'!M33)/1000,0)
B25: Revenue synergies (gross) — from 'Rev Synergy Bottom-Up' | C25: ='Synergies'!$H$48*C17 | D25: ='Synergies'!$H$48*D17 | E25: ='Synergies'!$H$48*E17 | F25: ='Synergies'!$H$48*F17 | G25: ='Synergies'!$H$48*G17
B26: Less: variable cost / COGS (implied by bottom-up EBIT) | C26: =C25-'Synergies'!$H$49*C17 | D26: =D25-'Synergies'!$H$49*D17 | E26: =E25-'Synergies'!$H$49*E17 | F26: =F25-'Synergies'!$H$49*F17 | G26: =G25-'Synergies'!$H$49*G17
B27: Revenue synergies (EBIT) | C27: =C25-C26 | D27: =D25-D26 | E27: =E25-E26 | F27: =F25-F26 | G27: =G25-G26
B28: Cost synergies — from 'Cost Synergy Bottom-Up' | C28: ='Synergies'!$H$32*C17 | D28: ='Synergies'!$H$32*D17 | E28: ='Synergies'!$H$32*E17 | F28: ='Synergies'!$H$32*F17 | G28: ='Synergies'!$H$32*G17
B29: Recurring pre-tax synergies NET of dissynergies (D3 transitional: yr1–3 only) | C29: =C27+C28+'Synergies'!$H$58*C17-'Dissynergy'!$F$30*1000 | D29: =D27+D28+'Synergies'!$H$58*D17-'Dissynergy'!$F$30*1000 | E29: =E27+E28+'Synergies'!$H$58*E17-'Dissynergy'!$F$30*1000 | F29: =F27+F28+'Synergies'!$H$58*F17-'Dissynergy'!$F$29*1000 | G29: =G27+G28+'Synergies'!$H$58*G17-'Dissynergy'!$F$29*1000
B30: Integration costs (one-time) | C30: =C28*$C$13*(1-C17+0.25) | D30: =D28*$C$13*(1-D17+0.25) | E30: =E28*$C$13*(1-E17+0.25) | F30: =F28*$C$13*(1-F17+0.25) | G30: =G28*$C$13*(1-G17+0.25)
B31: Pre-tax net synergies | C31: =C29-C30 | D31: =D29-D30 | E31: =E29-E30 | F31: =F29-F30 | G31: =G29-G30
B32: After-tax recurring synergies | C32: =C29*(1-$C$6) | D32: =D29*(1-$C$6) | E32: =E29*(1-$C$6) | F32: =F29*(1-$C$6) | G32: =G29*(1-$C$6)
B33: After-tax net synergies | C33: =C31*(1-$C$6) | D33: =D31*(1-$C$6) | E33: =E31*(1-$C$6) | F33: =F31*(1-$C$6) | G33: =G31*(1-$C$6)
B34: Discount factor | C34: =IFERROR(1/(1+$C$7)^(1),0) | D34: =IFERROR(1/(1+$C$7)^(2),0) | E34: =IFERROR(1/(1+$C$7)^(3),0) | F34: =IFERROR(1/(1+$C$7)^(4),0) | G34: =IFERROR(1/(1+$C$7)^(5),0)
B35: PV of recurring synergies | C35: =C32*C34 | D35: =D32*D34 | E35: =E32*E34 | F35: =F32*F34 | G35: =G32*G34
B36: PV of net synergies | C36: =C33*C34 | D36: =D33*D34 | E36: =E33*E34 | F36: =F33*F34 | G36: =G33*G34
B37: of which: Financing synergy (pre-tax, incl. above) | C37: ='Synergies'!$H$58*C17 | D37: ='Synergies'!$H$58*D17 | E37: ='Synergies'!$H$58*E17 | F37: ='Synergies'!$H$58*F17 | G37: ='Synergies'!$H$58*G17
B38: Synergy terminal value
B40: Terminal value - perpetuity | C40: =IFERROR(G32*(1+$C$8)/($C$7-$C$8),0)
B41: PV of terminal value | C41: =C40*G34
B42: Terminal value - exit multiple | C42: =(G27+G28)*$C$9
B43: PV of exit multiple terminal value | C43: =C42*G34
B44: Synergy NPV (perpetuity) | C44: =SUM(C35:G35)+C41-SUMPRODUCT(C30:G30*(1-$C$6),C34:G34)
B45: Synergy NPV (exit multiple) | C45: =SUM(C35:G35)+C43-SUMPRODUCT(C30:G30*(1-$C$6),C34:G34)
B46: Cost synergy now bottom-up in 'Cost Synergy Bottom-Up'; financing synergy added as a new component from 'Fin Synergy Bottom-Up' (interest saving, in row 29 & 37). Exit-multiple TV intentionally excludes financing.
...

Sheet M&A_Valuation
B2: TOWR + WIFI valuation bridge
B3: standalone DCF (linked to WIFI VALUATION) + synergy NPV + offer bridge
B5: Target standalone DCF | I5: Pro forma accretion / dilution
B6: Target tax rate | C6: =-'WIFI 3-Statement Model'!H43/'WIFI 3-Statement Model'!H42
B7: Target WACC | C7: =Synergy_Schedule!C7 | I7: Buyer standalone EPS | J7: ='Merger-Model'!F60
B8: Terminal growth | C8: =Synergy_Schedule!C8 | I8: Pro forma combined EPS | J8: ='Merger-Model'!F90
I9: Accretion / dilution % | J9: ='Merger-Model'!F94
C10: ='WIFI 3-Statement Model'!I2 | D10: ='WIFI 3-Statement Model'!J2 | E10: ='WIFI 3-Statement Model'!K2 | F10: ='WIFI 3-Statement Model'!L2 | G10: ='WIFI 3-Statement Model'!M2 | I10: Cash funding % | J10: ='Merger-Model'!F8
B11: Revenue | C11: =IFERROR('WIFI 3-Statement Model'!I28/1000,0) | D11: =IFERROR('WIFI 3-Statement Model'!J28/1000,0) | E11: =IFERROR('WIFI 3-Statement Model'!K28/1000,0) | F11: =IFERROR('WIFI 3-Statement Model'!L28/1000,0) | G11: =IFERROR('WIFI 3-Statement Model'!M28/1000,0) | I11: Stock funding % | J11: ='Merger-Model'!F10
B12: EBIT | C12: =IFERROR('WIFI 3-Statement Model'!I34/1000,0) | D12: =IFERROR('WIFI 3-Statement Model'!J34/1000,0) | E12: =IFERROR('WIFI 3-Statement Model'!K34/1000,0) | F12: =IFERROR('WIFI 3-Statement Model'!L34/1000,0) | G12: =IFERROR('WIFI 3-Statement Model'!M34/1000,0)
B13: Tax on EBIT | C13: =C12*$C$6 | D13: =D12*$C$6 | E13: =E12*$C$6 | F13: =F12*$C$6 | G13: =G12*$C$6
B14: NOPAT | C14: =C12-C13 | D14: =D12-D13 | E14: =E12-E13 | F14: =F12-F13 | G14: =G12-G13
B15: Depreciation & amortization | C15: =IFERROR('WIFI 3-Statement Model'!I36/1000,0) | D15: =IFERROR('WIFI 3-Statement Model'!J36/1000,0) | E15: =IFERROR('WIFI 3-Statement Model'!K36/1000,0) | F15: =IFERROR('WIFI 3-Statement Model'!L36/1000,0) | G15: =IFERROR('WIFI 3-Statement Model'!M36/1000,0)
B16: Capex | C16: =IFERROR('WIFI 3-Statement Model'!I113/1000,0) | D16: =IFERROR('WIFI 3-Statement Model'!J113/1000,0) | E16: =IFERROR('WIFI 3-Statement Model'!K113/1000,0) | F16: =IFERROR('WIFI 3-Statement Model'!L113/1000,0) | G16: =IFERROR('WIFI 3-Statement Model'!M113/1000,0)
B17: Change in NWC (fixed: WIFI r120, source/(use)) | C17: =-IFERROR('WIFI 3-Statement Model'!I120/1000,0) | D17: =-IFERROR('WIFI 3-Statement Model'!J120/1000,0) | E17: =-IFERROR('WIFI 3-Statement Model'!K120/1000,0) | F17: =-IFERROR('WIFI 3-Statement Model'!L120/1000,0) | G17: =-IFERROR('WIFI 3-Statement Model'!M120/1000,0)
B18: Unlevered FCF | C18: =C14+C15-C16-C17 | D18: =D14+D15-D16-D17 | E18: =E14+E15-E16-E17 | F18: =F14+F15-F16-F17 | G18: =G14+G15-G16-G17
B19: Discount factor | C19: =IFERROR(1/(1+$C$7)^(1),0) | D19: =IFERROR(1/(1+$C$7)^(2),0) | E19: =IFERROR(1/(1+$C$7)^(3),0) | F19: =IFERROR(1/(1+$C$7)^(4),0) | G19: =IFERROR(1/(1+$C$7)^(5),0)
B20: PV of FCF | C20: =C18*C19 | D20: =D18*D19 | E20: =E18*E19 | F20: =F18*F19 | G20: =G18*G19
B22: Terminal value (reference only - not used; see C24) | C22: =IFERROR(G18*(1+$C$8)/($C$7-$C$8),0)
B23: PV of terminal (reference only) | C23: =C22*G19
B24: Standalone target EV (from WIFI VALUATION, calibrated DCF) | C24: ='WIFI VALUATION'!H22/1000
B25: Less: target cash | C25: ='Merger-Shares-BS'!E16
B26: Plus: target debt | C26: ='Merger-Shares-BS'!E17
B27: Plus: minority interest | C27: ='WIFI VALUATION'!H24/1000
B28: Standalone target equity value | C28: =C24+C25-C26-C27
B29: Implied standalone value / share (IDR) | C29: =IFERROR(C28*1000/Control!$B$17,0)
B31: Offer price / share (IDR) | C31: =Purchase_Price
B32: Offer equity value | C32: ='Merger-Model'!$L$7
B33: Offer enterprise value | C33: =C32+Control!$B$19-Control!$B$18
B35: Synergy NPV (perpetuity) | C35: =Synergy_Schedule!$C$44
B36: Synergy NPV (exit multiple) | C36: =Synergy_Schedule!$C$45
B37: Buyer affordable EV incl. synergies (perpetuity) | C37: =C24+C35
B38: Buyer affordable EV incl. synergies (exit multiple) | C38: =C24+C36
B39: Offer EV premium vs standalone DCF | C39: =IFERROR(C33/C24-1,0)
B40: Offer EV discount/(premium) vs synergy-backed EV | C40: =IFERROR(C33/C37-1,0)

Sheet OJK Compliance
B2: OJK Regulatory Checklist — Acquisition of a Listed Company
B3: TOWR acquiring 51% of WIFI (Tbk) → change of control. Verified against OJK regulations (see sources).
B5: Regulation / trigger | C5: What it requires | D5: Impact on this deal
B6: POJK 9/POJK.04/2018 — Pengambilalihan (Takeover) | C6: Buying >50% voting shares OR gaining control = becoming 'Pengendali' (Art 1(4)). Acquiring 51% triggers a MANDATORY TENDER OFFER (Penawaran Tender Wajib) to all remaining public shareholders. | D6: TRIGGERED. TOWR must launch an MTO for the ~49% public float.
B7: MTO price floor (POJK 9/2018, Art 17) | C7: For listed & liquid shares, MTO price ≥ the HIGHER of: (a) the acquisition price paid for control, or (b) the average of the highest daily prices over the 90 days before announcement. | D7: Offer @35% = Rp2.822 > 90-day high (~Rp2.530), so the acquisition price sets the floor. TOWR must pay Rp2.822 to ALL tendering public holders — a higher premium raises total cash sharply.
B8: MTO timeline (POJK 9/2018, Art 7/14/16) | C8: Announce in a newspaper + file with OJK (Art 7); 30-day offer period (Art 14); settle within 12 days; report results to OJK within 5 days (Art 16). | D8: Plan announcement + 30-day tender window into the deal timetable.
B9: Refloat requirement (POJK 9/2018, Art 21) | C9: If after the MTO the controller holds >80% of capital, it must divest so the public again holds ≥20%, within a maximum of 2 years. | D9: If take-up is high, TOWR may need to sell down to keep ≥20% public float within 2 years.
B10: POJK 17/POJK.04/2020 — Transaksi Material | C10: Transaction value ≥20% of equity → public disclosure + independent appraiser (KJPP) report. >50% → also independent-shareholder RUPS approval. | D10: The WIFI stake is material for TOWR → disclosure + KJPP fairness opinion required (RUPS if it crosses 50% of TOWR equity).
B11: POJK 42/POJK.04/2020 — Transaksi Afiliasi / Benturan Kepentingan | C11: If buyer & target are affiliated or a conflict of interest exists: independent appraiser fairness opinion + disclosure + independent-shareholder approval. Exempt if <0.5% of paid-up capital or <Rp5bn. | D11: Check TOWR–WIFI affiliation (common controllers). If affiliated → independent RUPS + KJPP fairness opinion needed.
B12: Independent appraiser (KJPP) | C12: A registered valuer must issue a valuation & fairness opinion supporting the offer price for MTO / material / affiliated transactions. | D12: This football field + valuation supports the fairness opinion; a licensed KJPP must formally sign off.
B14: Key takeaway for offer price: because the MTO floor = the control-acquisition price extended to the full 49% public float, every extra point of premium is paid on ~100% of shares, not just the 51% block. This is a strong reason to keep the premium disciplined (≈35%) rather than pushing toward the blended ceiling (~73%).
B17: Sources
B18: • POJK No. 9/POJK.04/2018 — Pengambilalihan Perusahaan Terbuka (ojk.go.id, full text PDF)
B19: • POJK No. 17/POJK.04/2020 — Transaksi Material dan Perubahan Kegiatan Usaha
B20: • POJK No. 42/POJK.04/2020 — Transaksi Afiliasi dan Transaksi Benturan Kepentingan

Sheet Football Field
B2: WIFI (Surge) — Valuation Football Field vs Offer Price
B3: Implied value per WIFI share (IDR). Low–Base = coklat muda · Base–High = coklat tua. Ties to the recommended 35% offer / MTO floor.
B5: Valuation method | C5: Low | D5: Base | E5: High | F5: Base vs market | G5: Source / note
B6: 52-week trading range | C6: 1365 | D6: 2090 | E6: 4250 | F6: =D6/2090-1 | G6: WIFI BETA daily price, last 52 weeks
B7: Relative — P/E peers | C7: 1320 | D7: 1782 | E7: 2353 | F7: =D7/2090-1 | G7: Comparable sheet: Worst/Base/Best (G53:G55)
B8: Relative — EV/EBITDA peers | C8: 1940 | D8: 2795 | E8: 4785 | F8: =D8/2090-1 | G8: Comparable sheet: Worst/Base/Best (E53:E55)
B9: Relative — P/BV peers | C9: 2028 | D9: 2475 | E9: 4675 | F9: =D9/2090-1 | G9: Comparable sheet: Worst/Base/Best (F53:F55)
B10: Sum-of-the-Parts (SOTP) | C10: 3082 | D10: 3424 | E10: 3767 | F10: =D10/2090-1 | G10: WIFI SOTP base Rp3,424 ± ~10% band
B11: DCF (WACC 9–11%) | C11: 3299 | D11: 3666 | E11: 4106 | F11: =D11/2090-1 | G11: WIFI VALUATION base Rp3,666; WACC sensitivity band
B12: Blended target | C12: 3295 | D12: 3619 | E12: 3666 | F12: =D12/2090-1 | G12: WIFI BLENDED: simple avg / weighted / top method
B13: Precedent (Indo→intl fiber) | C13: 2900 | D13: 4847 | E13: 6794 | F13: =D13/2090-1 | G13: OUTLIER, 10% weight — intl EV/homepass (Verizon/AT&T). Verify.
B15: Offer-price references
B16: Reference | C16: Rp/share | D16: Premium vs market
B17: Market price (21 Aug) | C17: 2090 | D17: =C17/2090-1
B18: Recommended offer @35% = MTO floor | C18: 2822 | D18: =C18/2090-1
B19: Blended fair value (ceiling) | C19: 3619 | D19: =C19/2090-1
B21: Reading: at 35% premium (Rp2.822) the offer sits ABOVE market and the relative-multiple base cases (P/E, EV/EBITDA, P/BV) but BELOW the intrinsic methods (SOTP, DCF, blended Rp3.619) — a real premium to holders with a margin of safety for TOWR. Under POJK 9/2018 this offer price also becomes the Mandatory Tender Offer floor extended to ALL public shareholders (see OJK Compliance tab).

Sheet Sensitivities
B2: TOWR + WIFI accretion / dilution sensitivities
B3: formula-based tables; no fragile Excel data tables
B5: Base buyer pre-tax income | C5: =IFERROR('TOWR-3-Statements'!G48/1000,0)
B6: Base seller pre-tax income | C6: =IFERROR('WIFI 3-Statement Model'!H42/1000,0)
B7: Buyer tax rate | C7: =Control!$B$11
B8: Buyer shares (000) | C8: =Control!$B$5
B9: Seller shares (000) | C9: =Control!$B$17
B10: Buyer share price | C10: =Control!$B$4
B11: Cash funding % | C11: ='Merger-Model'!$F$8
B12: Debt funding % | C12: ='Merger-Model'!$F$9
B13: Stock funding % | C13: ='Merger-Model'!$F$10
B14: Foregone cash rate | C14: =Control!$B$12
B15: Debt rate | C15: =Control!$B$13
B16: Seller 2026 revenue | C16: =IFERROR('WIFI 3-Statement Model'!I28/1000,0)
B17: Seller 2026 OpEx ex D&A | C17: =IFERROR(-('WIFI 3-Statement Model'!I32+'WIFI 3-Statement Model'!I33)/1000,0)
B18: Blended rev-synergy margin (data-linked) | C18: ='Synergies'!J45/'Synergies'!H45 | D18: EBIT ÷ gross rev (margin segmen aktual — ganti 60% legacy)
B20: 2026 EPS accretion / dilution: purchase premium vs cost synergies
B22: Cost synergy % | D22: 0.1 | E22: 0.2 | F22: 0.3 | G22: 0.4 | H22: 0.5
B23: 0 | D23: =IFERROR((((((($C$5+$C$6+($C$17*$B23))*(1-$C$7)-((Control!$B$16*(1+D$22)*Control!$B$17/1000)*$C$11*$C$14)-((Control!$B$16*(1+D$22)*Control!$B$17/1000)*$C$12*$C$15))/($C$8+((Control!$B$16*(1+D$22)*Control!$B$17/1000)*$C$13/Control!$B$4*1000)))*1000)-'Merger-Model'!F60)/'Merger-Model'!F60),0) | E23: =IFERROR((((((($C$5+$C$6+($C$17*$B23))*(1-$C$7)-((Control!$B$16*(1+E$22)*Control!$B$17/1000)*$C$11*$C$14)-((Control!$B$16*(1+E$22)*Control!$B$17/1000)*$C$12*$C$15))/($C$8+((Control!$B$16*(1+E$22)*Control!$B$17/1000)*$C$13/Control!$B$4*1000)))*1000)-'Merger-Model'!F60)/'Merger-Model'!F60),0) | F23: =IFERROR((((((($C$5+$C$6+($C$17*$B23))*(1-$C$7)-((Control!$B$16*(1+F$22)*Control!$B$17/1000)*$C$11*$C$14)-((Control!$B$16*(1+F$22)*Control!$B$17/1000)*$C$12*$C$15))/($C$8+((Control!$B$16*(1+F$22)*Control!$B$17/1000)*$C$13/Control!$B$4*1000)))*1000)-'Merger-Model'!F60)/'Merger-Model'!F60),0) | G23: =IFERROR((((((($C$5+$C$6+($C$17*$B23))*(1-$C$7)-((Control!$B$16*(1+G$22)*Control!$B$17/1000)*$C$11*$C$14)-((Control!$B$16*(1+G$22)*Control!$B$17/1000)*$C$12*$C$15))/($C$8+((Control!$B$16*(1+G$22)*Control!$B$17/1000)*$C$13/Control!$B$4*1000)))*1000)-'Merger-Model'!F60)/'Merger-Model'!F60),0) | H23: =IFERROR((((((($C$5+$C$6+($C$17*$B23))*(1-$C$7)-((Control!$B$16*(1+H$22)*Control!$B$17/1000)*$C$11*$C$14)-((Control!$B$16*(1+H$22)*Control!$B$17/1000)*$C$12*$C$15))/($C$8+((Control!$B$16*(1+H$22)*Control!$B$17/1000)*$C$13/Control!$B$4*1000)))*1000)-'Merger-Model'!F60)/'Merger-Model'!F60),0)
B24: 0.025 | D24: =IFERROR((((((($C$5+$C$6+($C$17*$B24))*(1-$C$7)-((Control!$B$16*(1+D$22)*Control!$B$17/1000)*$C$11*$C$14)-((Control!$B$16*(1+D$22)*Control!$B$17/1000)*$C$12*$C$15))/($C$8+((Control!$B$16*(1+D$22)*Control!$B$17/1000)*$C$13/Control!$B$4*1000)))*1000)-'Merger-Model'!F60)/'Merger-Model'!F60),0) | E24: =IFERROR((((((($C$5+$C$6+($C$17*$B24))*(1-$C$7)-((Control!$B$16*(1+E$22)*Control!$B$17/1000)*$C$11*$C$14)-((Control!$B$16*(1+E$22)*Control!$B$17/1000)*$C$12*$C$15))/($C$8+((Control!$B$16*(1+E$22)*Control!$B$17/1000)*$C$13/Control!$B$4*1000)))*1000)-'Merger-Model'!F60)/'Merger-Model'!F60),0) | F24: =IFERROR((((((($C$5+$C$6+($C$17*$B24))*(1-$C$7)-((Control!$B$16*(1+F$22)*Control!$B$17/1000)*$C$11*$C$14)-((Control!$B$16*(1+F$22)*Control!$B$17/1000)*$C$12*$C$15))/($C$8+((Control!$B$16*(1+F$22)*Control!$B$17/1000)*$C$13/Control!$B$4*1000)))*1000)-'Merger-Model'!F60)/'Merger-Model'!F60),0) | G24: =IFERROR((((((($C$5+$C$6+($C$17*$B24))*(1-$C$7)-((Control!$B$16*(1+G$22)*Control!$B$17/1000)*$C$11*$C$14)-((Control!$B$16*(1+G$22)*Control!$B$17/1000)*$C$12*$C$15))/($C$8+((Control!$B$16*(1+G$22)*Control!$B$17/1000)*$C$13/Control!$B$4*1000)))*1000)-'Merger-Model'!F60)/'Merger-Model'!F60),0) | H24: =IFERROR((((((($C$5+$C$6+($C$17*$B24))*(1-$C$7)-((Control!$B$16*(1+H$22)*Control!$B$17/1000)*$C$11*$C$14)-((Control!$B$16*(1+H$22)*Control!$B$17/1000)*$C$12*$C$15))/($C$8+((Control!$B$16*(1+H$22)*Control!$B$17/1000)*$C$13/Control!$B$4*1000)))*1000)-'Merger-Model'!F60)/'Merger-Model'!F60),0)
B25: 0.05 | D25: =IFERROR((((((($C$5+$C$6+($C$17*$B25))*(1-$C$7)-((Control!$B$16*(1+D$22)*Control!$B$17/1000)*$C$11*$C$14)-((Control!$B$16*(1+D$22)*Control!$B$17/1000)*$C$12*$C$15))/($C$8+((Control!$B$16*(1+D$22)*Control!$B$17/1000)*$C$13/Control!$B$4*1000)))*1000)-'Merger-Model'!F60)/'Merger-Model'!F60),0) | E25: =IFERROR((((((($C$5+$C$6+($C$17*$B25))*(1-$C$7)-((Control!$B$16*(1+E$22)*Control!$B$17/1000)*$C$11*$C$14)-((Control!$B$16*(1+E$22)*Control!$B$17/1000)*$C$12*$C$15))/($C$8+((Control!$B$16*(1+E$22)*Control!$B$17/1000)*$C$13/Control!$B$4*1000)))*1000)-'Merger-Model'!F60)/'Merger-Model'!F60),0) | F25: =IFERROR((((((($C$5+$C$6+($C$17*$B25))*(1-$C$7)-((Control!$B$16*(1+F$22)*Control!$B$17/1000)*$C$11*$C$14)-((Control!$B$16*(1+F$22)*Control!$B$17/1000)*$C$12*$C$15))/($C$8+((Control!$B$16*(1+F$22)*Control!$B$17/1000)*$C$13/Control!$B$4*1000)))*1000)-'Merger-Model'!F60)/'Merger-Model'!F60),0) | G25: =IFERROR((((((($C$5+$C$6+($C$17*$B25))*(1-$C$7)-((Control!$B$16*(1+G$22)*Control!$B$17/1000)*$C$11*$C$14)-((Control!$B$16*(1+G$22)*Control!$B$17/1000)*$C$12*$C$15))/($C$8+((Control!$B$16*(1+G$22)*Control!$B$17/1000)*$C$13/Control!$B$4*1000)))*1000)-'Merger-Model'!F60)/'Merger-Model'!F60),0) | H25: =IFERROR((((((($C$5+$C$6+($C$17*$B25))*(1-$C$7)-((Control!$B$16*(1+H$22)*Control!$B$17/1000)*$C$11*$C$14)-((Control!$B$16*(1+H$22)*Control!$B$17/1000)*$C$12*$C$15))/($C$8+((Control!$B$16*(1+H$22)*Control!$B$17/1000)*$C$13/Control!$B$4*1000)))*1000)-'Merger-Model'!F60)/'Merger-Model'!F60),0)
B26: 0.075 | D26: =IFERROR((((((($C$5+$C$6+($C$17*$B26))*(1-$C$7)-((Control!$B$16*(1+D$22)*Control!$B$17/1000)*$C$11*$C$14)-((Control!$B$16*(1+D$22)*Control!$B$17/1000)*$C$12*$C$15))/($C$8+((Control!$B$16*(1+D$22)*Control!$B$17/1000)*$C$13/Control!$B$4*1000)))*1000)-'Merger-Model'!F60)/'Merger-Model'!F60),0) | E26: =IFERROR((((((($C$5+$C$6+($C$17*$B26))*(1-$C$7)-((Control!$B$16*(1+E$22)*Control!$B$17/1000)*$C$11*$C$14)-((Control!$B$16*(1+E$22)*Control!$B$17/1000)*$C$12*$C$15))/($C$8+((Control!$B$16*(1+E$22)*Control!$B$17/1000)*$C$13/Control!$B$4*1000)))*1000)-'Merger-Model'!F60)/'Merger-Model'!F60),0) | F26: =IFERROR((((((($C$5+$C$6+($C$17*$B26))*(1-$C$7)-((Control!$B$16*(1+F$22)*Control!$B$17/1000)*$C$11*$C$14)-((Control!$B$16*(1+F$22)*Control!$B$17/1000)*$C$12*$C$15))/($C$8+((Control!$B$16*(1+F$22)*Control!$B$17/1000)*$C$13/Control!$B$4*1000)))*1000)-'Merger-Model'!F60)/'Merger-Model'!F60),0) | G26: =IFERROR((((((($C$5+$C$6+($C$17*$B26))*(1-$C$7)-((Control!$B$16*(1+G$22)*Control!$B$17/1000)*$C$11*$C$14)-((Control!$B$16*(1+G$22)*Control!$B$17/1000)*$C$12*$C$15))/($C$8+((Control!$B$16*(1+G$22)*Control!$B$17/1000)*$C$13/Control!$B$4*1000)))*1000)-'Merger-Model'!F60)/'Merger-Model'!F60),0) | H26: =IFERROR((((((($C$5+$C$6+($C$17*$B26))*(1-$C$7)-((Control!$B$16*(1+H$22)*Control!$B$17/1000)*$C$11*$C$14)-((Control!$B$16*(1+H$22)*Control!$B$17/1000)*$C$12*$C$15))/($C$8+((Control!$B$16*(1+H$22)*Control!$B$17/1000)*$C$13/Control!$B$4*1000)))*1000)-'Merger-Model'!F60)/'Merger-Model'!F60),0)
B27: 0.1 | D27: =IFERROR((((((($C$5+$C$6+($C$17*$B27))*(1-$C$7)-((Control!$B$16*(1+D$22)*Control!$B$17/1000)*$C$11*$C$14)-((Control!$B$16*(1+D$22)*Control!$B$17/1000)*$C$12*$C$15))/($C$8+((Control!$B$16*(1+D$22)*Control!$B$17/1000)*$C$13/Control!$B$4*1000)))*1000)-'Merger-Model'!F60)/'Merger-Model'!F60),0) | E27: =IFERROR((((((($C$5+$C$6+($C$17*$B27))*(1-$C$7)-((Control!$B$16*(1+E$22)*Control!$B$17/1000)*$C$11*$C$14)-((Control!$B$16*(1+E$22)*Control!$B$17/1000)*$C$12*$C$15))/($C$8+((Control!$B$16*(1+E$22)*Control!$B$17/1000)*$C$13/Control!$B$4*1000)))*1000)-'Merger-Model'!F60)/'Merger-Model'!F60),0) | F27: =IFERROR((((((($C$5+$C$6+($C$17*$B27))*(1-$C$7)-((Control!$B$16*(1+F$22)*Control!$B$17/1000)*$C$11*$C$14)-((Control!$B$16*(1+F$22)*Control!$B$17/1000)*$C$12*$C$15))/($C$8+((Control!$B$16*(1+F$22)*Control!$B$17/1000)*$C$13/Control!$B$4*1000)))*1000)-'Merger-Model'!F60)/'Merger-Model'!F60),0) | G27: =IFERROR((((((($C$5+$C$6+($C$17*$B27))*(1-$C$7)-((Control!$B$16*(1+G$22)*Control!$B$17/1000)*$C$11*$C$14)-((Control!$B$16*(1+G$22)*Control!$B$17/1000)*$C$12*$C$15))/($C$8+((Control!$B$16*(1+G$22)*Control!$B$17/1000)*$C$13/Control!$B$4*1000)))*1000)-'Merger-Model'!F60)/'Merger-Model'!F60),0) | H27: =IFERROR((((((($C$5+$C$6+($C$17*$B27))*(1-$C$7)-((Control!$B$16*(1+H$22)*Control!$B$17/1000)*$C$11*$C$14)-((Control!$B$16*(1+H$22)*Control!$B$17/1000)*$C$12*$C$15))/($C$8+((Control!$B$16*(1+H$22)*Control!$B$17/1000)*$C$13/Control!$B$4*1000)))*1000)-'Merger-Model'!F60)/'Merger-Model'!F60),0)
B31: 2026 EPS accretion / dilution: purchase premium vs revenue synergies
B33: Revenue synergy % | D33: 0.1 | E33: 0.2 | F33: 0.3 | G33: 0.4 | H33: 0.5
B34: 0 | D34: =IFERROR((((((($C$5+$C$6+($C$16*$B34*$C$18))*(1-$C$7)-((Control!$B$16*(1+D$33)*Control!$B$17/1000)*$C$11*$C$14)-((Control!$B$16*(1+D$33)*Control!$B$17/1000)*$C$12*$C$15))/($C$8+((Control!$B$16*(1+D$33)*Control!$B$17/1000)*$C$13/Control!$B$4*1000)))*1000)-'Merger-Model'!F60)/'Merger-Model'!F60),0) | E34: =IFERROR((((((($C$5+$C$6+($C$16*$B34*$C$18))*(1-$C$7)-((Control!$B$16*(1+E$33)*Control!$B$17/1000)*$C$11*$C$14)-((Control!$B$16*(1+E$33)*Control!$B$17/1000)*$C$12*$C$15))/($C$8+((Control!$B$16*(1+E$33)*Control!$B$17/1000)*$C$13/Control!$B$4*1000)))*1000)-'Merger-Model'!F60)/'Merger-Model'!F60),0) | F34: =IFERROR((((((($C$5+$C$6+($C$16*$B34*$C$18))*(1-$C$7)-((Control!$B$16*(1+F$33)*Control!$B$17/1000)*$C$11*$C$14)-((Control!$B$16*(1+F$33)*Control!$B$17/1000)*$C$12*$C$15))/($C$8+((Control!$B$16*(1+F$33)*Control!$B$17/1000)*$C$13/Control!$B$4*1000)))*1000)-'Merger-Model'!F60)/'Merger-Model'!F60),0) | G34: =IFERROR((((((($C$5+$C$6+($C$16*$B34*$C$18))*(1-$C$7)-((Control!$B$16*(1+G$33)*Control!$B$17/1000)*$C$11*$C$14)-((Control!$B$16*(1+G$33)*Control!$B$17/1000)*$C$12*$C$15))/($C$8+((Control!$B$16*(1+G$33)*Control!$B$17/1000)*$C$13/Control!$B$4*1000)))*1000)-'Merger-Model'!F60)/'Merger-Model'!F60),0) | H34: =IFERROR((((((($C$5+$C$6+($C$16*$B34*$C$18))*(1-$C$7)-((Control!$B$16*(1+H$33)*Control!$B$17/1000)*$C$11*$C$14)-((Control!$B$16*(1+H$33)*Control!$B$17/1000)*$C$12*$C$15))/($C$8+((Control!$B$16*(1+H$33)*Control!$B$17/1000)*$C$13/Control!$B$4*1000)))*1000)-'Merger-Model'!F60)/'Merger-Model'!F60),0)
B35: 0.01 | D35: =IFERROR((((((($C$5+$C$6+($C$16*$B35*$C$18))*(1-$C$7)-((Control!$B$16*(1+D$33)*Control!$B$17/1000)*$C$11*$C$14)-((Control!$B$16*(1+D$33)*Control!$B$17/1000)*$C$12*$C$15))/($C$8+((Control!$B$16*(1+D$33)*Control!$B$17/1000)*$C$13/Control!$B$4*1000)))*1000)-'Merger-Model'!F60)/'Merger-Model'!F60),0) | E35: =IFERROR((((((($C$5+$C$6+($C$16*$B35*$C$18))*(1-$C$7)-((Control!$B$16*(1+E$33)*Control!$B$17/1000)*$C$11*$C$14)-((Control!$B$16*(1+E$33)*Control!$B$17/1000)*$C$12*$C$15))/($C$8+((Control!$B$16*(1+E$33)*Control!$B$17/1000)*$C$13/Control!$B$4*1000)))*1000)-'Merger-Model'!F60)/'Merger-Model'!F60),0) | F35: =IFERROR((((((($C$5+$C$6+($C$16*$B35*$C$18))*(1-$C$7)-((Control!$B$16*(1+F$33)*Control!$B$17/1000)*$C$11*$C$14)-((Control!$B$16*(1+F$33)*Control!$B$17/1000)*$C$12*$C$15))/($C$8+((Control!$B$16*(1+F$33)*Control!$B$17/1000)*$C$13/Control!$B$4*1000)))*1000)-'Merger-Model'!F60)/'Merger-Model'!F60),0) | G35: =IFERROR((((((($C$5+$C$6+($C$16*$B35*$C$18))*(1-$C$7)-((Control!$B$16*(1+G$33)*Control!$B$17/1000)*$C$11*$C$14)-((Control!$B$16*(1+G$33)*Control!$B$17/1000)*$C$12*$C$15))/($C$8+((Control!$B$16*(1+G$33)*Control!$B$17/1000)*$C$13/Control!$B$4*1000)))*1000)-'Merger-Model'!F60)/'Merger-Model'!F60),0) | H35: =IFERROR((((((($C$5+$C$6+($C$16*$B35*$C$18))*(1-$C$7)-((Control!$B$16*(1+H$33)*Control!$B$17/1000)*$C$11*$C$14)-((Control!$B$16*(1+H$33)*Control!$B$17/1000)*$C$12*$C$15))/($C$8+((Control!$B$16*(1+H$33)*Control!$B$17/1000)*$C$13/Control!$B$4*1000)))*1000)-'Merger-Model'!F60)/'Merger-Model'!F60),0)
B36: 0.02 | D36: =IFERROR((((((($C$5+$C$6+($C$16*$B36*$C$18))*(1-$C$7)-((Control!$B$16*(1+D$33)*Control!$B$17/1000)*$C$11*$C$14)-((Control!$B$16*(1+D$33)*Control!$B$17/1000)*$C$12*$C$15))/($C$8+((Control!$B$16*(1+D$33)*Control!$B$17/1000)*$C$13/Control!$B$4*1000)))*1000)-'Merger-Model'!F60)/'Merger-Model'!F60),0) | E36: =IFERROR((((((($C$5+$C$6+($C$16*$B36*$C$18))*(1-$C$7)-((Control!$B$16*(1+E$33)*Control!$B$17/1000)*$C$11*$C$14)-((Control!$B$16*(1+E$33)*Control!$B$17/1000)*$C$12*$C$15))/($C$8+((Control!$B$16*(1+E$33)*Control!$B$17/1000)*$C$13/Control!$B$4*1000)))*1000)-'Merger-Model'!F60)/'Merger-Model'!F60),0) | F36: =IFERROR((((((($C$5+$C$6+($C$16*$B36*$C$18))*(1-$C$7)-((Control!$B$16*(1+F$33)*Control!$B$17/1000)*$C$11*$C$14)-((Control!$B$16*(1+F$33)*Control!$B$17/1000)*$C$12*$C$15))/($C$8+((Control!$B$16*(1+F$33)*Control!$B$17/1000)*$C$13/Control!$B$4*1000)))*1000)-'Merger-Model'!F60)/'Merger-Model'!F60),0) | G36: =IFERROR((((((($C$5+$C$6+($C$16*$B36*$C$18))*(1-$C$7)-((Control!$B$16*(1+G$33)*Control!$B$17/1000)*$C$11*$C$14)-((Control!$B$16*(1+G$33)*Control!$B$17/1000)*$C$12*$C$15))/($C$8+((Control!$B$16*(1+G$33)*Control!$B$17/1000)*$C$13/Control!$B$4*1000)))*1000)-'Merger-Model'!F60)/'Merger-Model'!F60),0) | H36: =IFERROR((((((($C$5+$C$6+($C$16*$B36*$C$18))*(1-$C$7)-((Control!$B$16*(1+H$33)*Control!$B$17/1000)*$C$11*$C$14)-((Control!$B$16*(1+H$33)*Control!$B$17/1000)*$C$12*$C$15))/($C$8+((Control!$B$16*(1+H$33)*Control!$B$17/1000)*$C$13/Control!$B$4*1000)))*1000)-'Merger-Model'!F60)/'Merger-Model'!F60),0)
B37: 0.03 | D37: =IFERROR((((((($C$5+$C$6+($C$16*$B37*$C$18))*(1-$C$7)-((Control!$B$16*(1+D$33)*Control!$B$17/1000)*$C$11*$C$14)-((Control!$B$16*(1+D$33)*Control!$B$17/1000)*$C$12*$C$15))/($C$8+((Control!$B$16*(1+D$33)*Control!$B$17/1000)*$C$13/Control!$B$4*1000)))*1000)-'Merger-Model'!F60)/'Merger-Model'!F60),0) | E37: =IFERROR((((((($C$5+$C$6+($C$16*$B37*$C$18))*(1-$C$7)-((Control!$B$16*(1+E$33)*Control!$B$17/1000)*$C$11*$C$14)-((Control!$B$16*(1+E$33)*Control!$B$17/1000)*$C$12*$C$15))/($C$8+((Control!$B$16*(1+E$33)*Control!$B$17/1000)*$C$13/Control!$B$4*1000)))*1000)-'Merger-Model'!F60)/'Merger-Model'!F60),0) | F37: =IFERROR((((((($C$5+$C$6+($C$16*$B37*$C$18))*(1-$C$7)-((Control!$B$16*(1+F$33)*Control!$B$17/1000)*$C$11*$C$14)-((Control!$B$16*(1+F$33)*Control!$B$17/1000)*$C$12*$C$15))/($C$8+((Control!$B$16*(1+F$33)*Control!$B$17/1000)*$C$13/Control!$B$4*1000)))*1000)-'Merger-Model'!F60)/'Merger-Model'!F60),0) | G37: =IFERROR((((((($C$5+$C$6+($C$16*$B37*$C$18))*(1-$C$7)-((Control!$B$16*(1+G$33)*Control!$B$17/1000)*$C$11*$C$14)-((Control!$B$16*(1+G$33)*Control!$B$17/1000)*$C$12*$C$15))/($C$8+((Control!$B$16*(1+G$33)*Control!$B$17/1000)*$C$13/Control!$B$4*1000)))*1000)-'Merger-Model'!F60)/'Merger-Model'!F60),0) | H37: =IFERROR((((((($C$5+$C$6+($C$16*$B37*$C$18))*(1-$C$7)-((Control!$B$16*(1+H$33)*Control!$B$17/1000)*$C$11*$C$14)-((Control!$B$16*(1+H$33)*Control!$B$17/1000)*$C$12*$C$15))/($C$8+((Control!$B$16*(1+H$33)*Control!$B$17/1000)*$C$13/Control!$B$4*1000)))*1000)-'Merger-Model'!F60)/'Merger-Model'!F60),0)
B38: 0.04 | D38: =IFERROR((((((($C$5+$C$6+($C$16*$B38*$C$18))*(1-$C$7)-((Control!$B$16*(1+D$33)*Control!$B$17/1000)*$C$11*$C$14)-((Control!$B$16*(1+D$33)*Control!$B$17/1000)*$C$12*$C$15))/($C$8+((Control!$B$16*(1+D$33)*Control!$B$17/1000)*$C$13/Control!$B$4*1000)))*1000)-'Merger-Model'!F60)/'Merger-Model'!F60),0) | E38: =IFERROR((((((($C$5+$C$6+($C$16*$B38*$C$18))*(1-$C$7)-((Control!$B$16*(1+E$33)*Control!$B$17/1000)*$C$11*$C$14)-((Control!$B$16*(1+E$33)*Control!$B$17/1000)*$C$12*$C$15))/($C$8+((Control!$B$16*(1+E$33)*Control!$B$17/1000)*$C$13/Control!$B$4*1000)))*1000)-'Merger-Model'!F60)/'Merger-Model'!F60),0) | F38: =IFERROR((((((($C$5+$C$6+($C$16*$B38*$C$18))*(1-$C$7)-((Control!$B$16*(1+F$33)*Control!$B$17/1000)*$C$11*$C$14)-((Control!$B$16*(1+F$33)*Control!$B$17/1000)*$C$12*$C$15))/($C$8+((Control!$B$16*(1+F$33)*Control!$B$17/1000)*$C$13/Control!$B$4*1000)))*1000)-'Merger-Model'!F60)/'Merger-Model'!F60),0) | G38: =IFERROR((((((($C$5+$C$6+($C$16*$B38*$C$18))*(1-$C$7)-((Control!$B$16*(1+G$33)*Control!$B$17/1000)*$C$11*$C$14)-((Control!$B$16*(1+G$33)*Control!$B$17/1000)*$C$12*$C$15))/($C$8+((Control!$B$16*(1+G$33)*Control!$B$17/1000)*$C$13/Control!$B$4*1000)))*1000)-'Merger-Model'!F60)/'Merger-Model'!F60),0) | H38: =IFERROR((((((($C$5+$C$6+($C$16*$B38*$C$18))*(1-$C$7)-((Control!$B$16*(1+H$33)*Control!$B$17/1000)*$C$11*$C$14)-((Control!$B$16*(1+H$33)*Control!$B$17/1000)*$C$12*$C$15))/($C$8+((Control!$B$16*(1+H$33)*Control!$B$17/1000)*$C$13/Control!$B$4*1000)))*1000)-'Merger-Model'!F60)/'Merger-Model'!F60),0)
B39: 0.05 | D39: =IFERROR((((((($C$5+$C$6+($C$16*$B39*$C$18))*(1-$C$7)-((Control!$B$16*(1+D$33)*Control!$B$17/1000)*$C$11*$C$14)-((Control!$B$16*(1+D$33)*Control!$B$17/1000)*$C$12*$C$15))/($C$8+((Control!$B$16*(1+D$33)*Control!$B$17/1000)*$C$13/Control!$B$4*1000)))*1000)-'Merger-Model'!F60)/'Merger-Model'!F60),0) | E39: =IFERROR((((((($C$5+$C$6+($C$16*$B39*$C$18))*(1-$C$7)-((Control!$B$16*(1+E$33)*Control!$B$17/1000)*$C$11*$C$14)-((Control!$B$16*(1+E$33)*Control!$B$17/1000)*$C$12*$C$15))/($C$8+((Control!$B$16*(1+E$33)*Control!$B$17/1000)*$C$13/Control!$B$4*1000)))*1000)-'Merger-Model'!F60)/'Merger-Model'!F60),0) | F39: =IFERROR((((((($C$5+$C$6+($C$16*$B39*$C$18))*(1-$C$7)-((Control!$B$16*(1+F$33)*Control!$B$17/1000)*$C$11*$C$14)-((Control!$B$16*(1+F$33)*Control!$B$17/1000)*$C$12*$C$15))/($C$8+((Control!$B$16*(1+F$33)*Control!$B$17/1000)*$C$13/Control!$B$4*1000)))*1000)-'Merger-Model'!F60)/'Merger-Model'!F60),0) | G39: =IFERROR((((((($C$5+$C$6+($C$16*$B39*$C$18))*(1-$C$7)-((Control!$B$16*(1+G$33)*Control!$B$17/1000)*$C$11*$C$14)-((Control!$B$16*(1+G$33)*Control!$B$17/1000)*$C$12*$C$15))/($C$8+((Control!$B$16*(1+G$33)*Control!$B$17/1000)*$C$13/Control!$B$4*1000)))*1000)-'Merger-Model'!F60)/'Merger-Model'!F60),0) | H39: =IFERROR((((((($C$5+$C$6+($C$16*$B39*$C$18))*(1-$C$7)-((Control!$B$16*(1+H$33)*Control!$B$17/1000)*$C$11*$C$14)-((Control!$B$16*(1+H$33)*Control!$B$17/1000)*$C$12*$C$15))/($C$8+((Control!$B$16*(1+H$33)*Control!$B$17/1000)*$C$13/Control!$B$4*1000)))*1000)-'Merger-Model'!F60)/'Merger-Model'!F60),0)
B41: Catatan: margin revenue synergy kini = margin segmen aktual (data-linked C18), bukan asumsi 60% legacy. Axis tetap % untuk what-if.
B43: Valuation cross-check
B45: Standalone target EV | C45: ='M&A_Valuation'!C24
B46: Offer EV | C46: ='M&A_Valuation'!C33
B47: Synergy NPV | C47: ='M&A_Valuation'!C35
B48: Affordable EV incl. synergies | C48: ='M&A_Valuation'!C37

Sheet Financing_Mix
A1: Financing Mix (Aligned to Merger-Model & Sensitivities)
A3: Model-Linked Financing Assumptions
A4: Purchase premium | B4: =Control!$B$10 | C4: Linked to Control and used in Merger-Model purchase price | E4: Interpretation
A5: % cash funding | B5: ='Merger-Model'!$F$8 | C5: Must match Sensitivities C11 | E5: Funding structure
A6: % debt funding | B6: ='Merger-Model'!$F$9 | C6: Must match Sensitivities C12 | E6: Cash coverage vs equity purchase price | F6: =IFERROR(B15/B24,0)
A7: % stock funding | B7: ='Merger-Model'!$F$10 | C7: Must match Sensitivities C13 | E7: Implied stock issuance as % of buyer shares | F7: =IFERROR(B27/B18,0)
A8: Foregone cash rate | B8: =Control!$B$12 | C8: Used in Sensitivities as financing drag on cash portion | E8: Estimated financing drag / buyer EBITDA | F8: =IFERROR(B33/B17,0)
A9: Debt interest rate | B9: =Control!$B$13 | C9: Used in Sensitivities as financing drag on debt portion | E9: Pro forma gross debt / EBITDA | F9: =B40
A10: Buyer tax rate | B10: =Control!$B$11 | C10: Applied to combined pre-tax earnings in sensitivities
A11: Buyer share price (IDR) | B11: =Control!$B$4 | C11: Used to translate stock consideration into new shares
A14: Buyer Standalone Position (FY2025) | E14: Metric | F14: Value
A15: Buyer cash (IDR mm) | B15: ='TOWR-3-Statements'!G59/1000 | C15: Cash & short-term securities | E15: Buyer cash | F15: =B15
A16: Buyer gross debt (IDR mm) | B16: =('TOWR-3-Statements'!G80+'TOWR-3-Statements'!G87)/1000 | C16: ST + LT debt | E16: Cash used | F16: =B25
A17: Buyer EBITDA (IDR mm) | B17: ='TOWR-3-Statements'!G41/1000 | C17: EBIT + D&A proxy | E17: Remaining cash | F17: =B38
A18: Buyer shares (000) | B18: =Control!$B$5 | C18: Diluted share count
A19: Buyer pre-deal EPS (IDR/share) | B19: ='Merger-Model'!F60 | C19: Base EPS used for accretion/dilution
A22: Sources & Uses (Directly Aligned to Merger-Model)
A23: Seller offer price / share (IDR) | B23: ='Merger-Model'!$F$7 | C23: Purchase price incl. premium
A24: Equity purchase price (IDR mm) | B24: ='Merger-Model'!$L$7 | C24: Used in Merger-Model rows 7-10
A25: Cash used (IDR mm) | B25: ='Merger-Model'!$L$8 | C25: Cash-funded portion
A26: Debt issued (IDR mm) | B26: ='Merger-Model'!$L$9 | C26: Debt-funded portion
A27: New shares issued (000) | B27: ='Merger-Model'!$L$10 | C27: Stock-funded portion translated into shares
A28: Stock consideration value (IDR mm) | B28: =B27*$B$11/1000 | C28: Implied value of stock consideration
A30: Financing Drag (Mirror of Sensitivities Formula Logic)
A31: Foregone cash cost (pre-tax, IDR mm) | B31: =B25*$B$8 | C31: Cash used × foregone cash rate
A32: Debt interest cost (pre-tax, IDR mm) | B32: =B26*$B$9 | C32: Debt issued × debt rate
A33: Total financing drag (pre-tax, IDR mm) | B33: =SUM(B31:B32) | C33: Directly mirrors cash and debt deductions in Sensitivities
A34: Estimated after-tax financing drag (IDR mm) | B34: =B33*(1-$B$10) | C34: Shown for analytical reference
A37: Pro Forma Capitalization & Balance Sheet Effects
A38: Remaining buyer cash after deal (IDR mm) | B38: =B15-B25 | C38: Post-deal cash balance
A39: Pro forma gross debt (IDR mm) | B39: =B16+B26 | C39: Buyer debt + new debt issued
A40: Pro forma net cash / (debt) (IDR mm) | B40: =B38-B39 | C40: Positive = net cash, negative = net debt
A41: Pro forma gross debt / EBITDA | B41: =IFERROR(B39/B17,0) | C41: Headline leverage after transaction
A42: Pro forma share count (000) | B42: =B18+B27 | C42: Buyer shares + new shares issued

Sheet Financing Strategy
A1: TOWR + WIFI | Financing Strategy (Section 4)
A2: All figures Rp bn. Linked to Control / Merger-Model. 51% acquisition, 60% debt / 40% equity funding.
A4: Key assumptions
A5: Run-rate synergy (full, Rp bn) | B5: 400
A6: Min. interest-coverage covenant (x) | B6: 2.5
A7: Bridge/acquisition debt rate | B7: =Control!B13
A8: Refloat proceeds (Rp bn) | B8: 10000
A10: A. LEVERAGE PROFILE ACROSS TENDER-ACCEPTANCE SCENARIOS
B11: Standalone | C11: Pro-forma 0% tender | D11: Pro-forma 50% tender | E11: Pro-forma 100% tender | F11: Post-refloat
A12: Net debt | B12: =('TOWR-3-Statements'!G80+'TOWR-3-Statements'!G87-'TOWR-3-Statements'!G59)/1000000 | C12: =B12+'Merger-Model'!L9/1000 | D12: =C12+0.5*(1-Control!B14)*'Merger-Shares-BS'!J15/1000 | E12: =C12+(1-Control!B14)*'Merger-Shares-BS'!J15/1000 | F12: =E12-B8
A13: EBITDA (+synergies post-refloat) | B13: ='TOWR-3-Statements'!G41/1000000 | C13: =('TOWR-3-Statements'!G41+'WIFI 3-Statement Model'!H37)/1000000 | D13: =C13 | E13: =C13 | F13: =C13+B5
A14: Net debt / EBITDA | B14: =B12/B13 | C14: =C12/C13 | D14: =D12/D13 | E14: =E12/E13 | F14: =F12/F13
A15: Interest expense | B15: =-'TOWR-3-Statements'!G44/1000000 | C15: =B15+(C12-B12)*$B$7 | D15: =B15+(D12-B12)*$B$7 | E15: =B15+(E12-B12)*$B$7 | F15: =B15+(F12-B12)*$B$7
A16: Interest coverage (EBITDA / interest) | B16: =B13/B15 | C16: =C13/C15 | D16: =D13/D15 | E16: =E13/E15 | F16: =F13/F15
A17: Debt / equity | B17: =('TOWR-3-Statements'!G80+'TOWR-3-Statements'!G87)/'TOWR-3-Statements'!G99 | C17: =(('TOWR-3-Statements'!G80+'TOWR-3-Statements'!G87)/1000000+'Merger-Model'!L9/1000)/(('TOWR-3-Statements'!G99)/1000000+'Merger-Model'!F10*'Merger-Model'!L7/1000) | D17: =C17 | E17: =C17 | F17: =C17
A18: Debt / total assets | B18: =('TOWR-3-Statements'!G80+'TOWR-3-Statements'!G87)/'TOWR-3-Statements'!G75 | C18: =(('TOWR-3-Statements'!G80+'TOWR-3-Statements'!G87)/1000000+'Merger-Model'!L9/1000)/('TOWR-3-Statements'!G75/1000000+'WIFI 3-Statement Model'!H62/1000000+'Merger-Model'!F28/1000) | D18: =C18 | E18: =C18 | F18: =C18
A20: B. COVENANT HEADROOM
A21: Binding covenant: interest coverage (tightest in infra credit agreements)
A22: Pro-forma interest coverage (0% tender) | B22: =C16
A23: Covenant floor | B23: =B6
A24: Headroom vs covenant (x) | B24: =B22-B23
A25: EBITDA decline to breach covenant | B25: =1-B23*C15/C13
A26: Full-tender interim coverage (pre-refloat) | B26: =E16
A27: Post-refloat coverage | B27: =F16
A29: C. CREDIT-RATING IMPLICATIONS
A30: • Leverage rises only modestly (4.07x -> 4.23x) as the 40% equity portion limits new debt.
A31: • Interest coverage is the tightest metric; kept above the covenant floor under the base case.
A32: • Full-tender acceptance pushes interim leverage to ~5.07x -> refloat timetable is a rating commitment.
A33: • Rating-preservation actions: pre-brief agencies, publish refloat & deleveraging schedule,
A34: retain option to raise the equity portion if rating indications weaken.
A35: • Target's net-cash position (Rp565bn) and Rp1,106bn incremental EBITDA cushion the added debt.

Sheet Returns Analysis
A1: TOWR + WIFI | Return Analysis (Section 5)
A2: Rp bn. Acquirer cash flow = 51% of target FCF + after-tax synergies - integration. Discounted at WACC.
A4: Assumptions
A5: WACC (acquirer) | B5: ='TOWR WACC'!D9
A6: Stake acquired | B6: =Control!B14
A7: Exit EV/EBITDA (terminal) | B7: 8.5
A8: Full run-rate synergy (Rp bn) — linked to bottom-up gross | B8: ='Synergies'!J45+'Synergies'!J30+'Synergies'!J56
A9: Synergy realization % — implied by bottom-up haircut | B9: =('Synergies'!M45+'Synergies'!M30+'Synergies'!M56)/B8
A10: Transaction cost (Rp bn) | B10: 310.5
A11: Integration cost total (Rp bn) | B11: 520
A12: Net tender cost after refloat (Rp bn) | B12: 850
A13: FWA expansion option value (Rp bn) | B13: 1120
A14: Tax rate | B14: =Control!B11
A16: A. ACQUIRER CASH FLOW, NPV, IRR & PAYBACK (base case)
B17: Year: | C17: 0 | D17: 1 | E17: 2 | F17: 3 | G17: 4 | H17: 5
A18: 51% controlling-block price | C18: =-'Merger-Model'!L7/1000
A19: Net tender cost (after refloat) | C19: =-B12
A20: Transaction cost | C20: =-B10
A21: 51% of target FCF | D21: =$B$6*'M&A_Valuation'!C18/1000 | E21: =$B$6*'M&A_Valuation'!D18/1000 | F21: =$B$6*'M&A_Valuation'!E18/1000 | G21: =$B$6*'M&A_Valuation'!F18/1000 | H21: =$B$6*'M&A_Valuation'!G18/1000
A22: After-tax synergies net of dissynergies (D1–D3 yr1–3; D1–D2 only from yr4 — D3 is transitional) | D22: =($B$8*$B$9*0.25-'Dissynergy'!$F$30)*(1-$B$14) | E22: =($B$8*$B$9*0.6-'Dissynergy'!$F$30)*(1-$B$14) | F22: =($B$8*$B$9*0.85-'Dissynergy'!$F$30)*(1-$B$14) | G22: =($B$8*$B$9*1-'Dissynergy'!$F$29)*(1-$B$14) | H22: =($B$8*$B$9*1-'Dissynergy'!$F$29)*(1-$B$14)
A23: Integration cost (yr1-2) | D23: =-B11/2 | E23: =-B11/2
A24: Terminal equity value (51% x [exit x EBITDA - net debt]) | H24: =$B$6*($B$7*'WIFI 3-Statement Model'!M37/1000000-('WIFI 3-Statement Model'!M66+'WIFI 3-Statement Model'!M71-'WIFI 3-Statement Model'!M51)/1000000)
A25: Net cash flow | C25: =SUM(C18:C24) | D25: =SUM(D18:D24) | E25: =SUM(E18:E24) | F25: =SUM(F18:F24) | G25: =SUM(G18:G24) | H25: =SUM(H18:H24)
A26: Discount factor | C26: =1/(1+$B$5)^0 | D26: =1/(1+$B$5)^1 | E26: =1/(1+$B$5)^2 | F26: =1/(1+$B$5)^3 | G26: =1/(1+$B$5)^4 | H26: =1/(1+$B$5)^5
A27: PV of net cash flow | C27: =C25*C26 | D27: =D25*D26 | E27: =E25*E26 | F27: =F25*F26 | G27: =G25*G26 | H27: =H25*H26
A28: Cumulative cash flow | C28: =C25 | D28: =C28+D25 | E28: =D28+E25 | F28: =E28+F25 | G28: =F28+G25 | H28: =G28+H25
A30: NPV | B30: =SUM(C27:H27)
A31: IRR | B31: =IRR(C25:H25)
A32: Payback period (years, incl. exit value) | B32: =IFERROR((SUMPRODUCT(--(C28:H28<0))-1)+(-INDEX(C28:H28,SUMPRODUCT(--(C28:H28<0))))/INDEX(C25:H25,SUMPRODUCT(--(C28:H28<0))+1),"beyond horizon")
A33: vs WACC hurdle | B33: =B31-B5
A34: Payback on operating CF only (excl. exit) | B34: "beyond 5-yr window"
A35: B. VALUE CREATION BRIDGE
A36: Standalone value of the 51% stake | B36: =$B$6*Control!B18/1000
A37: PV of risk-adjusted synergies | B37: =SUMPRODUCT(D22:H22,D26:H26)+(H22/($B$5-0.03))*H26
A38: Option value of FWA expansion | B38: =B13
A39: Less: acquisition premium paid | B39: =-('Merger-Model'!L7/1000-B36)
A40: Less: integration cost | B40: =-B11
A41: Less: transaction cost | B41: =-B10
A42: Less: net tender-offer cost | B42: =-B12
A43: NET VALUE CREATION (all-in: synergies − dissynergies − costs + one-time) | B43: =SUM(B37:B42)+B44
...

Sheet Synergies
A1: SYNERGIES — Consolidated Bottom-Up (Cost · Revenue · Financing)
A2: All figures IDR bn unless stated. Blue = input · Green = link to another sheet · Black = formula. Single source feeding Synergy_Schedule, Merger-Model, Sensitivities & Returns Analysis.
A4: ASSUMPTIONS & REFERENCE DATA
B5: Modelling basis (1 = Gross · 2 = Risk-adjusted) | D5: 2
B7: Reference data — actual FY2025 (filings)
B8: WIFI cash SG&A ex-advertising & D&A | D8: 176.7 | O8: Surge AR2025: 211.9 − 22.4 ad − 12.8 D&A
B9: WIFI cost of revenue — unclassified | D9: 349.5 | O9: SOURCE WIFI IS 2025
B10: TOWR cost of revenue — unclassified | D10: 1115.1 | O10: SOURCE TOWR IS 2025
B11: STARLITE revenue (for 20% commission) | D11: 541.1 | O11: Surge AR p.104
B12: TOWR towers | D12: 36247 | O12: SMN AR2025 p.47
B13: TOWR revenue per tenant (IDR bn) | D13: 0.1442 | O13: 8,730 ÷ 60,540
B14: TOWR FTTH home passes (unpenetrated) | D14: 1954000 | O14: 2.34m × (1−16.6%), SMN AR2025 p.158
B15: STARLITE FTTH subscribers | D15: 1500000 | O15: Surge AR2025 p.104
B16: IRA FWA pre-registrations | D16: 1000000 | O16: Surge AR2025 p.106
B17: WIFI B2B / enterprise revenue (IDR bn) | D17: 668.2 | O17: Surge AR2025 (40.3% of revenue)
B18: WIFI broadband tariff (IDR bn/yr) | D18: 0.0012 | O18: Rp100k/month
B19: TOWR cost of debt (Kd, pre-tax) | D19: ='TOWR WACC'!D15 | O19: Link TOWR WACC
A21: A. COST SYNERGIES (run-rate, IDR bn)
